<robot
  name="mobile_bot">
  



  <gazebo>
    <plugin filename="libgazebo_ros_diff_drive.so" name="differential_drive_controller">
      <legacyMode>false</legacyMode>
      <alwaysOn>true</alwaysOn>
      <updateRate>20</updateRate>
      <leftJoint>left_wheel_joint</leftJoint>
      <rightJoint>right_wheel_joint</rightJoint>
      <wheelSeparation>0.4</wheelSeparation>
      <wheelDiameter>0.2</wheelDiameter>
      <torque>20</torque>
      <commandTopic>cmd_vel</commandTopic>
      <odometryTopic>odom</odometryTopic>
      <odometryFrame>odom</odometryFrame>
      <robotBaseFrame>base_link</robotBaseFrame>
    </plugin>



  </gazebo>
  <gazebo reference="base_link">
    <material>Gazebo/Orange</material>
  </gazebo>
  <gazebo reference="left_wheel_link">
    <material>Gazebo/Blue</material>
  </gazebo>
  <gazebo reference="right_wheel_link">
    <material>Gazebo/Blue</material>
  </gazebo>
  <gazebo reference="aux_link">
    <material>Gazebo/Red</material>
  </gazebo>



  <link
    name="base_link">
    <inertial>
      <origin
        xyz="-0.00622184359431738 0 -0.047659128690172"
        rpy="0 0 0" />
      <mass
        value="16.7087028099849" />
      <inertia
        ixx="0.160357541339885"
        ixy="-5.57452292081756E-17"
        ixz="-0.0066103014196117"
        iyy="0.420002910112563"
        iyz="-5.47104712094305E-19"
        izz="0.55283314314957" />
    </inertial>
    <visual>
      <origin
        xyz="0 0 0"
        rpy="0 0 0" />
      <geometry>
        <mesh
          filename="package://mobile_bot/meshes/base_link.STL" />
      </geometry>
      <material
        name="">
        <color
          rgba="1 0 0 1" />
      </material>
    </visual>
    <collision>
      <origin
        xyz="0 0 0"
        rpy="0 0 0" />
      <geometry>
        <mesh
          filename="package://mobile_bot/meshes/base_link.STL" />
      </geometry>
    </collision>
  </link>
  <link
    name="left_wheel_link">
    <inertial>
      <origin
        xyz="0 -0.0375 0"
        rpy="0 0 0" />
      <mass
        value="2.35619449019235" />
      <inertia
        ixx="0.00699495239275853"
        ixy="1.35525271560688E-19"
        ixz="1.69657916167962E-50"
        iyy="0.0117809724509617"
        iyz="-1.70747651256053E-35"
        izz="0.00699495239275852" />
    </inertial>
    <visual>
      <origin
        xyz="0 0 0"
        rpy="0 0 0" />
      <geometry>
        <mesh
          filename="package://mobile_bot/meshes/left_wheel_link.STL" />
      </geometry>
      <material
        name="">
        <color
          rgba="1 0.941176470588235 0.435294117647059 1" />
      </material>
    </visual>
    <collision>
      <origin
        xyz="0 0 0"
        rpy="0 0 0" />
      <geometry>
        <mesh
          filename="package://mobile_bot/meshes/left_wheel_link.STL" />
      </geometry>
    </collision>
  </link>
  <joint
    name="left_wheel_joint"
    type="continuous">
    <origin
      xyz="0.15 0.24 -0.0744721543908269"
      rpy="0 0 0" />
    <parent
      link="base_link" />
    <child
      link="left_wheel_link" />
    <axis
      xyz="0 1 0" />
  </joint>
  <link
    name="right_wheel_link">
    <inertial>
      <origin
        xyz="0 0.0375 0"
        rpy="0 0 0" />
      <mass
        value="2.35619449019234" />
      <inertia
        ixx="0.00699495239275852"
        ixy="6.77626357803441E-20"
        ixz="-2.03287907341032E-19"
        iyy="0.0117809724509617"
        iyz="6.24669226564202E-35"
        izz="0.00699495239275852" />
    </inertial>
    <visual>
      <origin
        xyz="0 0 0"
        rpy="0 0 0" />
      <geometry>
        <mesh
          filename="package://mobile_bot/meshes/right_wheel_link.STL" />
      </geometry>
      <material
        name="">
        <color
          rgba="1 0.941176470588235 0.435294117647059 1" />
      </material>
    </visual>
    <collision>
      <origin
        xyz="0 0 0"
        rpy="0 0 0" />
      <geometry>
        <mesh
          filename="package://mobile_bot/meshes/right_wheel_link.STL" />
      </geometry>
    </collision>
  </link>
  <joint
    name="right_wheel_joint"
    type="continuous">
    <origin
      xyz="0.15 -0.24 -0.0744721543908269"
      rpy="0 0 0" />
    <parent
      link="base_link" />
    <child
      link="right_wheel_link" />
    <axis
      xyz="0 1 0" />
  </joint>
  <link
    name="aux_link">
    <inertial>
      <origin
        xyz="0 0 1.1102E-16"
        rpy="0 0 0" />
      <mass
        value="0.17959" />
      <inertia
        ixx="8.8001E-05"
        ixy="0"
        ixz="0"
        iyy="8.8001E-05"
        iyz="0"
        izz="8.8001E-05" />
    </inertial>
    <visual>
      <origin
        xyz="0 0 0"
        rpy="0 0 0" />
      <geometry>
        <mesh
          filename="package://mobile_bot/meshes/aux_link.STL" />
      </geometry>
      <material
        name="">
        <color
          rgba="0.79216 0.81961 0.93333 1" />
      </material>
    </visual>
    <collision>
      <origin
        xyz="0 0 0"
        rpy="0 0 0" />
      <geometry>
        <mesh
          filename="package://mobile_bot/meshes/aux_link.STL" />
      </geometry>
    </collision>
  </link>
  <joint
    name="aux_wheel_joint"
    type="continuous">
    <origin
      xyz="-0.155 0 -0.135"
      rpy="0 0 0" />
    <parent
      link="base_link" />
    <child
      link="aux_link" />
    <axis
      xyz="0 1 0" />
  </joint>


</robot>